[2023-10-09T03:15:57.056+0000] {taskinstance.py:1157} INFO - Dependencies all met for dep_context=non-requeueable deps ti=<TaskInstance: mongo_data_loader.generate_dump manual__2023-10-09T03:15:52.135634+00:00 [queued]>
[2023-10-09T03:15:57.060+0000] {taskinstance.py:1157} INFO - Dependencies all met for dep_context=requeueable deps ti=<TaskInstance: mongo_data_loader.generate_dump manual__2023-10-09T03:15:52.135634+00:00 [queued]>
[2023-10-09T03:15:57.060+0000] {taskinstance.py:1359} INFO - Starting attempt 1 of 1
[2023-10-09T03:15:57.067+0000] {taskinstance.py:1380} INFO - Executing <Task(_PythonDecoratedOperator): generate_dump> on 2023-10-09 03:15:52.135634+00:00
[2023-10-09T03:15:57.073+0000] {standard_task_runner.py:57} INFO - Started process 781 to run task
[2023-10-09T03:15:57.076+0000] {standard_task_runner.py:84} INFO - Running: ['***', 'tasks', 'run', 'mongo_data_loader', 'generate_dump', 'manual__2023-10-09T03:15:52.135634+00:00', '--job-id', '7', '--raw', '--subdir', 'DAGS_FOLDER/mongo_data_loader.py', '--cfg-path', '/tmp/tmpv9osft49']
[2023-10-09T03:15:57.078+0000] {standard_task_runner.py:85} INFO - Job 7: Subtask generate_dump
[2023-10-09T03:15:57.105+0000] {task_command.py:415} INFO - Running <TaskInstance: mongo_data_loader.generate_dump manual__2023-10-09T03:15:52.135634+00:00 [running]> on host 9212e4845c65
[2023-10-09T03:15:57.140+0000] {taskinstance.py:1660} INFO - Exporting env vars: AIRFLOW_CTX_DAG_EMAIL='varunm1210@gmail.com,maitraisharma905@gmail.com' AIRFLOW_CTX_DAG_OWNER='***' AIRFLOW_CTX_DAG_ID='mongo_data_loader' AIRFLOW_CTX_TASK_ID='generate_dump' AIRFLOW_CTX_EXECUTION_DATE='2023-10-09T03:15:52.135634+00:00' AIRFLOW_CTX_TRY_NUMBER='1' AIRFLOW_CTX_DAG_RUN_ID='manual__2023-10-09T03:15:52.135634+00:00'
[2023-10-09T03:15:57.141+0000] {taskinstance.py:1935} ERROR - Task failed with exception
Traceback (most recent call last):
  File "/home/airflow/.local/lib/python3.8/site-packages/airflow/decorators/base.py", line 221, in execute
    return_value = super().execute(context)
  File "/home/airflow/.local/lib/python3.8/site-packages/airflow/operators/python.py", line 192, in execute
    return_value = self.execute_callable()
  File "/home/airflow/.local/lib/python3.8/site-packages/airflow/operators/python.py", line 209, in execute_callable
    return self.python_callable(*self.op_args, **self.op_kwargs)
  File "/opt/airflow/dags/mongo_data_loader.py", line 28, in generate_dump
    generate_raw_dump.generate_job_dump()
TypeError: generate_job_dump() missing 1 required positional argument: 'search_params'
[2023-10-09T03:15:57.146+0000] {taskinstance.py:1398} INFO - Marking task as FAILED. dag_id=mongo_data_loader, task_id=generate_dump, execution_date=20231009T031552, start_date=20231009T031557, end_date=20231009T031557
[2023-10-09T03:15:57.152+0000] {warnings.py:109} WARNING - /home/***/.local/lib/python3.8/site-packages/***/utils/email.py:154: RemovedInAirflow3Warning: Fetching SMTP credentials from configuration variables will be deprecated in a future release. Please set credentials using a connection instead.
  send_mime_email(e_from=mail_from, e_to=recipients, mime_msg=msg, conn_id=conn_id, dryrun=dryrun)

[2023-10-09T03:15:57.152+0000] {configuration.py:1063} WARNING - section/key [smtp/smtp_user] not found in config
[2023-10-09T03:15:57.153+0000] {email.py:270} INFO - Email alerting: attempt 1
[2023-10-09T03:15:57.157+0000] {configuration.py:1063} WARNING - section/key [smtp/smtp_user] not found in config
[2023-10-09T03:15:57.157+0000] {email.py:270} INFO - Email alerting: attempt 1
[2023-10-09T03:15:57.158+0000] {taskinstance.py:2005} ERROR - Failed to send email to: ['varunm1210@gmail.com', 'maitraisharma905@gmail.com']
Traceback (most recent call last):
  File "/home/airflow/.local/lib/python3.8/site-packages/airflow/models/taskinstance.py", line 1516, in _run_raw_task
    self._execute_task_with_callbacks(context, test_mode, session=session)
  File "/home/airflow/.local/lib/python3.8/site-packages/airflow/models/taskinstance.py", line 1679, in _execute_task_with_callbacks
    result = self._execute_task(context, task_orig)
  File "/home/airflow/.local/lib/python3.8/site-packages/airflow/models/taskinstance.py", line 1742, in _execute_task
    result = execute_callable(context=context, **execute_callable_kwargs)
  File "/home/airflow/.local/lib/python3.8/site-packages/airflow/decorators/base.py", line 221, in execute
    return_value = super().execute(context)
  File "/home/airflow/.local/lib/python3.8/site-packages/airflow/operators/python.py", line 192, in execute
    return_value = self.execute_callable()
  File "/home/airflow/.local/lib/python3.8/site-packages/airflow/operators/python.py", line 209, in execute_callable
    return self.python_callable(*self.op_args, **self.op_kwargs)
  File "/opt/airflow/dags/mongo_data_loader.py", line 28, in generate_dump
    generate_raw_dump.generate_job_dump()
TypeError: generate_job_dump() missing 1 required positional argument: 'search_params'

During handling of the above exception, another exception occurred:

Traceback (most recent call last):
  File "/home/airflow/.local/lib/python3.8/site-packages/airflow/models/taskinstance.py", line 2418, in email_alert
    send_email(task.email, subject, html_content)
  File "/home/airflow/.local/lib/python3.8/site-packages/airflow/utils/email.py", line 80, in send_email
    return backend(
  File "/home/airflow/.local/lib/python3.8/site-packages/airflow/utils/email.py", line 154, in send_email_smtp
    send_mime_email(e_from=mail_from, e_to=recipients, mime_msg=msg, conn_id=conn_id, dryrun=dryrun)
  File "/home/airflow/.local/lib/python3.8/site-packages/airflow/utils/email.py", line 272, in send_mime_email
    smtp_conn = _get_smtp_connection(smtp_host, smtp_port, smtp_timeout, smtp_ssl)
  File "/home/airflow/.local/lib/python3.8/site-packages/airflow/utils/email.py", line 317, in _get_smtp_connection
    return smtplib.SMTP(host=host, port=port, timeout=timeout)
  File "/usr/local/lib/python3.8/smtplib.py", line 255, in __init__
    (code, msg) = self.connect(host, port)
  File "/usr/local/lib/python3.8/smtplib.py", line 339, in connect
    self.sock = self._get_socket(host, port, self.timeout)
  File "/usr/local/lib/python3.8/smtplib.py", line 310, in _get_socket
    return socket.create_connection((host, port), timeout,
  File "/usr/local/lib/python3.8/socket.py", line 808, in create_connection
    raise err
  File "/usr/local/lib/python3.8/socket.py", line 796, in create_connection
    sock.connect(sa)
OSError: [Errno 99] Cannot assign requested address

During handling of the above exception, another exception occurred:

Traceback (most recent call last):
  File "/home/airflow/.local/lib/python3.8/site-packages/airflow/models/taskinstance.py", line 2003, in handle_failure
    self.email_alert(error, task)
  File "/home/airflow/.local/lib/python3.8/site-packages/airflow/models/taskinstance.py", line 2420, in email_alert
    send_email(task.email, subject, html_content_err)
  File "/home/airflow/.local/lib/python3.8/site-packages/airflow/utils/email.py", line 80, in send_email
    return backend(
  File "/home/airflow/.local/lib/python3.8/site-packages/airflow/utils/email.py", line 154, in send_email_smtp
    send_mime_email(e_from=mail_from, e_to=recipients, mime_msg=msg, conn_id=conn_id, dryrun=dryrun)
  File "/home/airflow/.local/lib/python3.8/site-packages/airflow/utils/email.py", line 272, in send_mime_email
    smtp_conn = _get_smtp_connection(smtp_host, smtp_port, smtp_timeout, smtp_ssl)
  File "/home/airflow/.local/lib/python3.8/site-packages/airflow/utils/email.py", line 317, in _get_smtp_connection
    return smtplib.SMTP(host=host, port=port, timeout=timeout)
  File "/usr/local/lib/python3.8/smtplib.py", line 255, in __init__
    (code, msg) = self.connect(host, port)
  File "/usr/local/lib/python3.8/smtplib.py", line 339, in connect
    self.sock = self._get_socket(host, port, self.timeout)
  File "/usr/local/lib/python3.8/smtplib.py", line 310, in _get_socket
    return socket.create_connection((host, port), timeout,
  File "/usr/local/lib/python3.8/socket.py", line 808, in create_connection
    raise err
  File "/usr/local/lib/python3.8/socket.py", line 796, in create_connection
    sock.connect(sa)
OSError: [Errno 99] Cannot assign requested address
[2023-10-09T03:15:57.165+0000] {standard_task_runner.py:104} ERROR - Failed to execute job 7 for task generate_dump (generate_job_dump() missing 1 required positional argument: 'search_params'; 781)
[2023-10-09T03:15:57.213+0000] {local_task_job_runner.py:228} INFO - Task exited with return code 1
[2023-10-09T03:15:57.224+0000] {taskinstance.py:2776} INFO - 0 downstream tasks scheduled from follow-on schedule check
