[2023-12-03T05:15:26.525+0000] {taskinstance.py:1157} INFO - Dependencies all met for dep_context=non-requeueable deps ti=<TaskInstance: mongo_data_loader.write_to_mongo manual__2023-12-03T05:12:37.041408+00:00 [queued]>
[2023-12-03T05:15:26.530+0000] {taskinstance.py:1157} INFO - Dependencies all met for dep_context=requeueable deps ti=<TaskInstance: mongo_data_loader.write_to_mongo manual__2023-12-03T05:12:37.041408+00:00 [queued]>
[2023-12-03T05:15:26.530+0000] {taskinstance.py:1359} INFO - Starting attempt 1 of 1
[2023-12-03T05:15:26.537+0000] {taskinstance.py:1380} INFO - Executing <Task(_PythonDecoratedOperator): write_to_mongo> on 2023-12-03 05:12:37.041408+00:00
[2023-12-03T05:15:26.541+0000] {standard_task_runner.py:57} INFO - Started process 179 to run task
[2023-12-03T05:15:26.544+0000] {standard_task_runner.py:84} INFO - Running: ['***', 'tasks', 'run', 'mongo_data_loader', 'write_to_mongo', 'manual__2023-12-03T05:12:37.041408+00:00', '--job-id', '32', '--raw', '--subdir', 'DAGS_FOLDER/mongo_data_loader.py', '--cfg-path', '/tmp/tmpcw2sip2z']
[2023-12-03T05:15:26.547+0000] {standard_task_runner.py:85} INFO - Job 32: Subtask write_to_mongo
[2023-12-03T05:15:26.577+0000] {task_command.py:415} INFO - Running <TaskInstance: mongo_data_loader.write_to_mongo manual__2023-12-03T05:12:37.041408+00:00 [running]> on host 0dd9b00a73f6
[2023-12-03T05:15:26.619+0000] {taskinstance.py:1660} INFO - Exporting env vars: AIRFLOW_CTX_DAG_OWNER='***' AIRFLOW_CTX_DAG_ID='mongo_data_loader' AIRFLOW_CTX_TASK_ID='write_to_mongo' AIRFLOW_CTX_EXECUTION_DATE='2023-12-03T05:12:37.041408+00:00' AIRFLOW_CTX_TRY_NUMBER='1' AIRFLOW_CTX_DAG_RUN_ID='manual__2023-12-03T05:12:37.041408+00:00'
[2023-12-03T05:15:26.708+0000] {taskinstance.py:1935} ERROR - Task failed with exception
Traceback (most recent call last):
  File "/home/airflow/.local/lib/python3.8/site-packages/airflow/decorators/base.py", line 221, in execute
    return_value = super().execute(context)
  File "/home/airflow/.local/lib/python3.8/site-packages/airflow/operators/python.py", line 192, in execute
    return_value = self.execute_callable()
  File "/home/airflow/.local/lib/python3.8/site-packages/airflow/operators/python.py", line 209, in execute_callable
    return self.python_callable(*self.op_args, **self.op_kwargs)
  File "/opt/airflow/dags/mongo_data_loader.py", line 44, in write_to_mongo
    mongo_write.insert_to_mongo()
  File "/opt/airflow/dags/mongo_write.py", line 28, in insert_to_mongo
    jobs_dict_list = read_json()
  File "/opt/airflow/dags/mongo_write.py", line 17, in read_json
    with open('{processed_file_path}processed_{current_date}.json'.format(processed_file_path=PROCESSED_FILE_BASE_PATH, current_date=datetime.now().strftime("%d_%m_%Y")), 'r') as file:
FileNotFoundError: [Errno 2] No such file or directory: '/opt/airflow/dags/processed-dump/processed_03_12_2023.json'
[2023-12-03T05:15:26.715+0000] {taskinstance.py:1398} INFO - Marking task as FAILED. dag_id=mongo_data_loader, task_id=write_to_mongo, execution_date=20231203T051237, start_date=20231203T051526, end_date=20231203T051526
[2023-12-03T05:15:26.722+0000] {standard_task_runner.py:104} ERROR - Failed to execute job 32 for task write_to_mongo ([Errno 2] No such file or directory: '/opt/airflow/dags/processed-dump/processed_03_12_2023.json'; 179)
[2023-12-03T05:15:26.760+0000] {local_task_job_runner.py:228} INFO - Task exited with return code 1
[2023-12-03T05:15:26.772+0000] {taskinstance.py:2776} INFO - 0 downstream tasks scheduled from follow-on schedule check
